<?xml version="1.0" ?>
<robot name="skid_steer" xmlns:xacro="http://www.ros.org/wiki/xacro">
  <xacro:arg name="is_gazebo_ign" default="true"/> 
  <xacro:include filename="$(find skid_steer_description)/urdf/materials.xacro" />
  <xacro:include filename="$(find skid_steer_description)/urdf/common_properties.xacro" />
  <xacro:include filename="$(find skid_steer_description)/urdf/skid_steer_control.xacro" />
  <xacro:include filename="$(find skid_steer_description)/urdf/skid_steer_gazebo.xacro" />
        <!-- AQUI EMPIEZA EL base_link Y BASE -->
    <link name="base_footprint"/>
    <link name="base_link">
      <inertial>
        <origin xyz="0 0 0" rpy="0 0 0"/>
        <mass value="18"/>
        <inertia ixx="0.104" iyy="0.118" izz="0.176" ixy="0.0" iyz="0.0" ixz="0.0"/>
      </inertial>
      <visual>
        <origin xyz="0 0 0" rpy="0 0 0"/>
        <geometry>
          <mesh filename="file://$(find skid_steer_description)/meshes/skid_steer_chasis_final.stl" scale="0.001 0.001 0.001"/> 
        </geometry>
        <material name="silver"/>
      </visual>
      <collision>
        <origin xyz="0 0 0" rpy="0 0 0"/>
        <geometry>
          <mesh filename="file://$(find skid_steer_description)/meshes/skid_steer_chasis_final.stl" scale="0.001 0.001 0.001"/>
        </geometry>
      </collision>
    </link>


    <joint name="base_joint" type="fixed">
            <parent link="base_footprint" />
            <child link="base_link" />
            <origin xyz="0 0 ${0.165875 + (0.118/2.0)}" rpy="0 0 0" />
    </joint>

    <!-- AQUI TERMINA EL base_link Y base_footprint -->


        <!-- AQUI EMPIEZAN LAS LLANTAS DERECHAS -->
    <link name="right_front_wheel_link">
      <inertial>
        <origin xyz="0 0 0" rpy="0 0 0"/>
        <mass value="0.140"/>
        <inertia ixx="1.88176298336665E-05" ixy="-4.8444933029987E-10" ixz="1.88163708851143E-08"
               iyy="3.11510738647764E-05" iyz="-6.93560663069607E-11"
               izz="1.8801969558182E-05" />
      </inertial>
      <visual>
        <origin xyz="0 -${0.057/2} 0" rpy="${pi/2} 0 0"/>
        <geometry>
          <cylinder radius="${0.118/2}" length="${0.057}" />
        </geometry>
        <material name="silver"/>
      </visual>
      <collision>
        <origin xyz="0 -${0.057/2} 0" rpy="${pi/2} 0 0"/>
        <geometry>
          <cylinder radius="${0.118/2}" length="${0.057}" />    
          </geometry>
      </collision>
    </link>

    <link name="right_mid_wheel_link">
      <inertial>
        <origin xyz="0 0 0" rpy="0 0 0"/>
        <mass value="0.140"/>
        <inertia ixx="1.88176298336665E-05" ixy="-4.8444933029987E-10" ixz="1.88163708851143E-08"
               iyy="3.11510738647764E-05" iyz="-6.93560663069607E-11"
               izz="1.8801969558182E-05" />
      </inertial>
      <visual>
        <origin xyz="0 -${0.057/2} 0" rpy="${pi/2} 0 0"/>
        <geometry>
          <cylinder radius="${0.118/2}" length="${0.057}" />
        </geometry>
        <material name="silver"/>
      </visual>
      <collision>
        <origin xyz="0 -${0.057/2} 0" rpy="${pi/2} 0 0"/>
        <geometry>
          <cylinder radius="${0.118/2}" length="${0.057}" />    
        </geometry>
      </collision>
    </link>
    
    <link name="right_back_wheel_link">
      <inertial>
        <origin xyz="0 0 0" rpy="0 0 0"/>
        <mass value="0.140"/>
        <inertia ixx="1.88176298336665E-05" ixy="-4.8444933029987E-10" ixz="1.88163708851143E-08"
               iyy="3.11510738647764E-05" iyz="-6.93560663069607E-11"
               izz="1.8801969558182E-05" />
      </inertial>
      <visual>
        <origin xyz="0 -${0.057/2} 0" rpy="${pi/2} 0 0"/>
        <geometry>
          <cylinder radius="${0.118/2}" length="${0.057}" />
        </geometry>
        <material name="silver"/>
      </visual>
      <collision>
        <origin xyz="0 -${0.057/2} 0" rpy="${pi/2} 0 0"/>
        <geometry>
          <cylinder radius="${0.118/2}" length="${0.057}" />    
        </geometry>
      </collision>
    </link>

    
    <joint name="base_right_front_wheel_joint" type="continuous">
            <parent link="base_link" />
            <child link="right_front_wheel_link" />
            <origin xyz="0.190 -0.273225 -0.165875" rpy="0 0 0" />
            <axis xyz="0 1 0" />
    </joint>
    <joint name="base_right_mid_wheel_joint" type="continuous">
            <parent link="base_link" />
            <child link="right_mid_wheel_link" />
            <origin xyz="0 -0.273225 -0.165875" rpy="0 0 0" />
            <axis xyz="0 1 0" />
    </joint>
    <joint name="base_right_back_wheel_joint" type="continuous">
            <parent link="base_link" />
            <child link="right_back_wheel_link" />
            <origin xyz="-0.190 -0.273225 -0.165875" rpy="0 0 0" />
            <axis xyz="0 1 0" />
    </joint>
    <!-- AQUI TERMINAN LAS LLANTAS DERECHAS -->


    <!-- AQUI EMPIEZAN LAS LLANTAS IZQUIERDAS -->
    <link name="left_front_wheel_link">
      <inertial>
        <origin xyz="0 0 0" rpy="0 0 0"/>
        <mass value="0.140"/>
        <inertia ixx="1.88176298336665E-05" ixy="-4.8444933029987E-10" ixz="1.88163708851143E-08"
               iyy="3.11510738647764E-05" iyz="-6.93560663069607E-11"
               izz="1.8801969558182E-05" />
      </inertial>
      <visual>
        <origin xyz="0 ${0.057/2} 0" rpy="${pi/2} 0 0"/>
        <geometry>
          <cylinder radius="${0.118/2}" length="${0.057}" />
        </geometry>
        <material name="silver"/>
      </visual>
      <collision>
        <origin xyz="0 ${0.057/2} 0" rpy="${pi/2} 0 0"/>
        <geometry>
          <cylinder radius="${0.118/2}" length="${0.057}" />    
        </geometry>
      </collision>
    </link>

    <link name="left_mid_wheel_link">
      <inertial>
        <origin xyz="0 0 0" rpy="0 0 0"/>
        <mass value="0.140"/>
        <inertia ixx="1.88176298336665E-05" ixy="-4.8444933029987E-10" ixz="1.88163708851143E-08"
               iyy="3.11510738647764E-05" iyz="-6.93560663069607E-11"
               izz="1.8801969558182E-05" />
      </inertial>
      <visual>
        <origin xyz="0 ${0.057/2} 0" rpy="${pi/2} 0 0"/>
        <geometry>
          <cylinder radius="${0.118/2}" length="${0.057}" />
        </geometry>
        <material name="silver"/>
      </visual>
      <collision>
        <origin xyz="0 ${0.057/2} 0" rpy="${pi/2} 0 0"/>
        <geometry>
          <cylinder radius="${0.118/2}" length="${0.057}" />    
        </geometry>
      </collision>
    </link>

    <link name="left_back_wheel_link">
      <inertial>
        <origin xyz="0 0 0" rpy="0 0 0"/>
        <mass value="0.140"/>
        <inertia ixx="1.88176298336665E-05" ixy="-4.8444933029987E-10" ixz="1.88163708851143E-08"
               iyy="3.11510738647764E-05" iyz="-6.93560663069607E-11"
               izz="1.8801969558182E-05" />
      </inertial>
      <visual>
        <origin xyz="0 ${0.057/2} 0" rpy="${pi/2} 0 0"/>
        <geometry>
          <cylinder radius="${0.118/2}" length="${0.057}" />
        </geometry>
        <material name="silver"/>
      </visual>
      <collision>
        <origin xyz="0 ${0.057/2} 0" rpy="${pi/2} 0 0"/>
        <geometry>
          <cylinder radius="${0.118/2}" length="${0.057}" />    
        </geometry>
      </collision>
    </link>


    <joint name="base_left_front_wheel_joint" type="continuous">
            <parent link="base_link" />
            <child link="left_front_wheel_link" />
            <origin xyz="0.190 0.273225 -0.165875" rpy="0 0 0" />
            <axis xyz="0 1 0" />
    </joint>
    <joint name="base_left_mid_wheel_joint" type="continuous">
            <parent link="base_link" />
            <child link="left_mid_wheel_link" />
            <origin xyz="0 0.273225 -0.165875" rpy="0 0 0" />
            <axis xyz="0 1 0" />
    </joint>
    <joint name="base_left_back_wheel_joint" type="continuous">
            <parent link="base_link" />
            <child link="left_back_wheel_link" />
            <origin xyz="-0.190 0.273225 -0.165875" rpy="0 0 0" />
            <axis xyz="0 1 0" />
    </joint>

    <!-- AQUI TERMINAN LAS LLANTAS IZQUIERDAS -->
    <!-- AQUI EMPIEZA EL IMU -->
    <link name="imu_link">
    <inertial>
      <origin xyz="-0.00552433659106688 0.000168210391520346 0.000514000497342681" rpy="0 0 0" />
      <mass value="0.000528415362211671" />
      <inertia ixx="1.46176048428261E-08" ixy="1.40015117949421E-10" ixz="-1.99633872937403E-12"
               iyy="8.59662482954888E-09" iyz="7.52375112767959E-12"
               izz="2.30279421279312E-08" />
    </inertial>
      <visual>
        <origin xyz="0 0 0" rpy="0 0 0" />
        <geometry>
          <mesh filename="package://skid_steer_description/meshes/imu_link.STL" />
        </geometry>
        <material name="">
          <color rgba="0.792156862745098 0.819607843137255 0.933333333333333 1" />
        </material>
      </visual>
      <collision>
        <origin xyz="0 0 0" rpy="0 0 0" />
        <geometry>
          <mesh filename="package://skid_steer_description/meshes/imu_link.STL" />
        </geometry>
      </collision>
  </link>
  
  <joint name="imu_joint" type="fixed">
    <origin xyz="0 0 0" rpy="0 0 0" />
    <parent link="base_link" />
    <child link="imu_link" />
    <axis xyz="0 0 0" />
  </joint>
  <!-- AQUI TERMINA EL IMU -->
  <!-- AQUI EMPIEZA EL LIDAR -->

  <link name="laser_link">
    <inertial>
      <origin xyz="-0.011945780406062 -0.000381929217680526 -0.0170649378129477" rpy="0 0 0" />
      <mass value="0.073084435549317" />
      <inertia ixx="1.96074931730795E-05" ixy="-3.62091076640009E-07" ixz="4.28230084046735E-07"
               iyy="2.40983835136327E-05" iyz="1.50180909250652E-08"
               izz="4.14184164228595E-05" />
    </inertial>
    <visual>
      <origin xyz="0 0 0" rpy="0 0 0" />
      <geometry>
        <mesh filename="package://skid_steer_description/meshes/laser_link.STL" />
      </geometry>
      <material name="">
        <color rgba="0.792156862745098 0.819607843137255 0.933333333333333 1" />
      </material>
    </visual>
    <collision>
      <origin xyz="0 0 0" rpy="0 0 0" />
      <geometry>
        <mesh filename="package://skid_steer_description/meshes/laser_link.STL" />
      </geometry>
    </collision>
  </link>

  <joint name="laser_joint" type="fixed">
    <origin xyz="0 0 ${(0.180/2.0)+0.031500}" rpy="0 0 0" />
    <parent link="base_link" />
    <child link="laser_link" />
    <axis xyz="0 0 0" />
  </joint>
  <!-- AQUI TERMINA EL LIAR -->
</robot>