<?xml version="1.0" ?>
<robot name="skid_steer" xmlns:xacro="http://www.ros.org/wiki/xacro">
  <xacro:arg name="is_gazebo_ign" default="true"/> 
  <xacro:include filename="$(find skid_steer_description)/urdf/materials.xacro" />
  <xacro:include filename="$(find skid_steer_description)/urdf/common_properties.xacro" />
  <xacro:include filename="$(find skid_steer_description)/urdf/skid_steer_control.xacro" />
  <xacro:include filename="$(find skid_steer_description)/urdf/skid_steer_gazebo.xacro" />
        <!-- AQUI EMPIEZA EL base_link Y BASE -->
    <link name="base_footprint"/>
    <link name="base_link">
      <inertial>
        <origin xyz="0 0 0" rpy="0 0 0"/>
        <mass value="18"/>
        <inertia ixx="0.104" iyy="0.118" izz="0.176" ixy="0.0" iyz="0.0" ixz="0.0"/>
      </inertial>
      <visual>
        <origin xyz="0 0 0" rpy="0 0 0"/>
        <geometry>
          <mesh filename="file://$(find skid_steer_description)/meshes/chasis_skid_steer_V2.stl" scale="0.001 0.001 0.001"/> <!-- <box size="0.4 0.3 0.2" /> -->
        </geometry>
        <material name="silver"/>
      </visual>
      <collision>
        <origin xyz="0 0 0" rpy="0 0 0"/>
        <geometry>
          <mesh filename="file://$(find skid_steer_description)/meshes/chasis_skid_steer_V2.stl" scale="0.001 0.001 0.001"/>
        </geometry>
      </collision>
    </link>


    <joint name="base_joint" type="fixed">
            <parent link="base_footprint" />
            <child link="base_link" />
            <origin xyz="0 0 ${0.165 + (0.118/2.0)}" rpy="0 0 0" />
    </joint>

    <!-- AQUI TERMINA EL base_link Y base_footprint -->


        <!-- AQUI EMPIEZAN LAS LLANTAS DERECHAS -->
    <link name="right_front_wheel_link">
      <inertial>
        <origin xyz="0 0 0" rpy="0 0 0"/>
        <mass value="0.140"/>
        <inertia ixx="0.0001" iyy="0.001" izz="0.001" ixy="0.0" iyz="0.0" ixz="0.0"/>
      </inertial>
      <visual>
        <origin xyz="0 -${0.057/2} 0" rpy="${pi/2} 0 0"/>
        <geometry>
          <cylinder radius="${0.118/2}" length="${0.057}" />
        </geometry>
        <material name="silver"/>
      </visual>
      <collision>
        <origin xyz="0 -${0.057/2} 0" rpy="${pi/2} 0 0"/>
        <geometry>
          <cylinder radius="${0.118/2}" length="${0.057}" />    </geometry>
      </collision>
    </link>

    <link name="right_mid_wheel_link">
      <inertial>
        <origin xyz="0 0 0" rpy="0 0 0"/>
        <mass value="0.140"/>
        <inertia ixx="0.0001" iyy="0.001" izz="0.001" ixy="0.0" iyz="0.0" ixz="0.0"/>
      </inertial>
      <visual>
        <origin xyz="0 -${0.057/2} 0" rpy="${pi/2} 0 0"/>
        <geometry>
          <cylinder radius="${0.118/2}" length="${0.057}" />
        </geometry>
        <material name="silver"/>
      </visual>
      <collision>
        <origin xyz="0 -${0.057/2} 0" rpy="${pi/2} 0 0"/>
        <geometry>
          <cylinder radius="${0.118/2}" length="${0.057}" />    </geometry>
      </collision>
    </link>
    
    <link name="right_back_wheel_link">
      <inertial>
        <origin xyz="0 0 0" rpy="0 0 0"/>
        <mass value="0.140"/>
        <inertia ixx="0.0001" iyy="0.001" izz="0.001" ixy="0.0" iyz="0.0" ixz="0.0"/>
      </inertial>
      <visual>
        <origin xyz="0 -${0.057/2} 0" rpy="${pi/2} 0 0"/>
        <geometry>
          <cylinder radius="${0.118/2}" length="${0.057}" />
        </geometry>
        <material name="silver"/>
      </visual>
      <collision>
        <origin xyz="0 -${0.057/2} 0" rpy="${pi/2} 0 0"/>
        <geometry>
          <cylinder radius="${0.118/2}" length="${0.057}" />    </geometry>
      </collision>
    </link>

    
    <joint name="base_right_front_wheel_joint" type="continuous">
            <parent link="base_link" />
            <child link="right_front_wheel_link" />
            <origin xyz="0.190 -0.278225 -0.165" rpy="0 0 0" />
            <axis xyz="0 1 0" />
    </joint>
    <joint name="base_right_mid_wheel_joint" type="continuous">
            <parent link="base_link" />
            <child link="right_mid_wheel_link" />
            <origin xyz="0 -0.278225 -0.165" rpy="0 0 0" />
            <axis xyz="0 1 0" />
    </joint>
    <joint name="base_right_back_wheel_joint" type="continuous">
            <parent link="base_link" />
            <child link="right_back_wheel_link" />
            <origin xyz="-0.190 -0.278225 -0.165" rpy="0 0 0" />
            <axis xyz="0 1 0" />
    </joint>
    <!-- AQUI TERMINAN LAS LLANTAS DERECHAS -->


    <!-- AQUI EMPIEZAN LAS LLANTAS IZQUIERDAS -->
    <link name="left_front_wheel_link">
      <inertial>
        <origin xyz="0 0 0" rpy="0 0 0"/>
        <mass value="0.140"/>
        <inertia ixx="0.0001" iyy="0.001" izz="0.001" ixy="0.0" iyz="0.0" ixz="0.0"/>
      </inertial>
      <visual>
        <origin xyz="0 ${0.057/2} 0" rpy="${pi/2} 0 0"/>
        <geometry>
          <cylinder radius="${0.118/2}" length="${0.057}" />
        </geometry>
        <material name="silver"/>
      </visual>
      <collision>
        <origin xyz="0 ${0.057/2} 0" rpy="${pi/2} 0 0"/>
        <geometry>
          <cylinder radius="${0.118/2}" length="${0.057}" />    </geometry>
      </collision>
    </link>

    <link name="left_mid_wheel_link">
      <inertial>
        <origin xyz="0 0 0" rpy="0 0 0"/>
        <mass value="0.140"/>
        <inertia ixx="0.0001" iyy="0.001" izz="0.001" ixy="0.0" iyz="0.0" ixz="0.0"/>
      </inertial>
      <visual>
        <origin xyz="0 ${0.057/2} 0" rpy="${pi/2} 0 0"/>
        <geometry>
          <cylinder radius="${0.118/2}" length="${0.057}" />
        </geometry>
        <material name="silver"/>
      </visual>
      <collision>
        <origin xyz="0 ${0.057/2} 0" rpy="${pi/2} 0 0"/>
        <geometry>
          <cylinder radius="${0.118/2}" length="${0.057}" />    </geometry>
      </collision>
    </link>

    <link name="left_back_wheel_link">
      <inertial>
        <origin xyz="0 0 0" rpy="0 0 0"/>
        <mass value="0.140"/>
        <inertia ixx="0.0001" iyy="0.001" izz="0.001" ixy="0.0" iyz="0.0" ixz="0.0"/>
      </inertial>
      <visual>
        <origin xyz="0 ${0.057/2} 0" rpy="${pi/2} 0 0"/>
        <geometry>
          <cylinder radius="${0.118/2}" length="${0.057}" />
        </geometry>
        <material name="silver"/>
      </visual>
      <collision>
        <origin xyz="0 ${0.057/2} 0" rpy="${pi/2} 0 0"/>
        <geometry>
          <cylinder radius="${0.118/2}" length="${0.057}" />    </geometry>
      </collision>
    </link>


    <joint name="base_left_front_wheel_joint" type="continuous">
            <parent link="base_link" />
            <child link="left_front_wheel_link" />
            <origin xyz="0.190 0.278225 -0.165" rpy="0 0 0" />
            <axis xyz="0 1 0" />
    </joint>
    <joint name="base_left_mid_wheel_joint" type="continuous">
            <parent link="base_link" />
            <child link="left_mid_wheel_link" />
            <origin xyz="0 0.278225 -0.165" rpy="0 0 0" />
            <axis xyz="0 1 0" />
    </joint>
    <joint name="base_left_back_wheel_joint" type="continuous">
            <parent link="base_link" />
            <child link="left_back_wheel_link" />
            <origin xyz="-0.190 0.278225 -0.165" rpy="0 0 0" />
            <axis xyz="0 1 0" />
    </joint>

    <!-- AQUI TERMINAN LAS LLANTAS IZQUIERDAS -->

</robot>